Workbook

Sheet Accueil
A1: TABLEAU DE BORD - GESTION DES STOCKS ET ACTIFS
A2: FTTH | GSM | BTP / Genie Civil | Logistique — Direction Generale — Mise a jour : 14/07/2026
A4: ARTICLES TOTAL | D4: VALEUR DU STOCK (FCFA) | G4: ARTICLES DISPONIBLES | J4: ARTICLES CRITIQUES
A5: =COUNTA(#REF!) -> 1 | D5: =SUM(#REF!) -> #REF! | G5: =COUNTIF(#REF!,"DISPONIBLE") -> #REF! | J5: =COUNTIF(#REF!,"CRITIQUE") -> #REF!
A8: ARTICLES EN RUPTURE | D8: ARTICLES EN COMMANDE | G8: ENTREES DU MOIS | J8: SORTIES DU MOIS
A9: =COUNTIF(#REF!,"RUPTURE") -> #REF! | D9: =COUNTIF(#REF!,">0") -> #REF! | G9: =IFERROR(SUMIFS(#REF!,#REF!,">="&DATE(YEAR(TODAY()),MONTH(TODAY()),1)),0) -> 0 | J9: =IFERROR(SUMIFS(#REF!,#REF!,">="&DATE(YEAR(TODAY()),MONTH(TODAY()),1)),0) -> 0
A12: EQUIPEMENTS AFFECTES | D12: EQUIPEMENTS DISPONIBLES | G12: EQUIPEMENTS DEFECTUEUX | J12: TAUX DE DISPONIBILITE EQUIP.
A13: =COUNTIF(#REF!,"Affecte") -> #REF! | D13: =COUNTIF(#REF!,"Disponible") -> #REF! | G13: =COUNTIFS(#REF!,"<>Disponible",#REF!,"<>Affecte") -> #REF! | J13: =IFERROR(COUNTIF(#REF!,"Disponible")/COUNTA(#REF!),0) -> 0
A16: TAUX DE ROTATION DU STOCK | D16: INVENTAIRE REALISE | I16: AUDITS OUVERTS
A17: =IFERROR(SUM(#REF!)/AVERAGE(#REF!),0) -> 0 | D17: ="N/A - module Inventaire a activer" -> N/A - module Inventaire a activer | I17: ="N/A - module Audit a activer" -> N/A - module Audit a activer
A40: ACCES RAPIDE AUX MODULES
A41: -> Base Articles | D41: -> Entrees | G41: -> Sorties | J41: -> Stock TempsReel
A43: -> Equipements | D43: -> Alertes | G43: -> Historique Import 2026 | J43: -> Parametres
A46: MODULE TRACABILITE MATERIEL
A47: -> Dashboard Tracabilite | D47: -> Projets | G47: -> Affectations | J47: -> Recherche Materiel
A49: -> Alertes Tracabilite
A60: Famille | B60: Nb articles | D60: Statut | E60: Nb
A61: FO | B61: =COUNTIF(#REF!,"FO") -> #REF! | D61: DISPONIBLE | E61: =COUNTIF(#REF!,"DISPONIBLE") -> #REF!
A62: GSM | B62: =COUNTIF(#REF!,"GSM") -> #REF! | D62: CRITIQUE | E62: =COUNTIF(#REF!,"CRITIQUE") -> #REF!
A63: BLR | B63: =COUNTIF(#REF!,"BLR") -> #REF! | D63: RUPTURE | E63: =COUNTIF(#REF!,"RUPTURE") -> #REF!
A64: NEW (a classer) | B64: =COUNTIF(#REF!,"BLR (a classer)") -> #REF! | D64: SURSTOCK | E64: =COUNTIF(#REF!,"SURSTOCK") -> #REF!

Sheet Dashboard_Tracabilite
A1: TABLEAU DE BORD - TRACABILITE DU MATERIEL PAR PROJET
A3: Filtrer par projet : | B3: (Tous)
A6: MATERIELS AFFECTES (PROJET FILTRE) | D6: MATERIELS EN MAINTENANCE | G6: MATERIELS NON RETOURNES (RETARD) | J6: MATERIELS PERDUS / VOLES
A7: =IF($B$3="(Tous)",COUNTIFS(#REF!,"",#REF!,"<>"),COUNTIFS(#REF!,$B$3,#REF!,"")) -> #REF! | D7: =IF($B$3="(Tous)",COUNTIF(#REF!,"En maintenance")+COUNTIF(#REF!,"En reparation"),COUNTIFS(#REF!,$B$3,#REF!,"En maintenance")) -> #REF! | G7: =IF($B$3="(Tous)",COUNTIF(#REF!,"OUI"),COUNTIFS(#REF!,$B$3,#REF!,"OUI")) -> #REF! | J7: =IF($B$3="(Tous)",COUNTIF(#REF!,"Perdu")+COUNTIF(#REF!,"Vole"),COUNTIFS(#REF!,$B$3,#REF!,"Perdu")+COUNTIFS(#REF!,$B$3,#REF!,"Vole")) -> #REF!
A10: MATERIELS REFORMES | D10: NOMBRE DE MOUVEMENTS (CE MOIS) | G10: DUREE MOYENNE D'AFFECTATION (JOURS) | J10: TAUX DE DISPONIBILITE EQUIPEMENTS
A11: =IF($B$3="(Tous)",COUNTIF(#REF!,"Reforme"),COUNTIFS(#REF!,$B$3,#REF!,"Reforme")) -> #REF! | D11: =IFERROR(SUMPRODUCT((#REF!>=DATE(YEAR(TODAY()),MONTH(TODAY()),1))*(#REF!<>"")*IF($B$3="(Tous)",1,#REF!=$B$3)),0) -> 0 | G11: =IFERROR(IF($B$3="(Tous)",AVERAGE(#REF!),AVERAGEIFS(#REF!,#REF!,$B$3)),0) -> 0 | J11: =IFERROR(COUNTIF(#REF!,"Disponible*")/COUNTA(#REF!),0) -> 0
A59: (Tous)
A60: =IFERROR(INDEX(#REF!,1),"")
A61: =IFERROR(INDEX(#REF!,2),"")
A62: =IFERROR(INDEX(#REF!,3),"")
A63: =IFERROR(INDEX(#REF!,4),"")
A64: =IFERROR(INDEX(#REF!,5),"")
A65: =IFERROR(INDEX(#REF!,6),"")
A66: =IFERROR(INDEX(#REF!,7),"")
A67: =IFERROR(INDEX(#REF!,8),"")
A68: =IFERROR(INDEX(#REF!,9),"")
A69: =IFERROR(INDEX(#REF!,10),"")
A70: =IFERROR(INDEX(#REF!,11),"")
A71: =IFERROR(INDEX(#REF!,12),"")
A72: =IFERROR(INDEX(#REF!,13),"")
A73: =IFERROR(INDEX(#REF!,14),"")
A74: =IFERROR(INDEX(#REF!,15),"")
A75: =IFERROR(INDEX(#REF!,16),"")
A76: =IFERROR(INDEX(#REF!,17),"")
A77: =IFERROR(INDEX(#REF!,18),"")
A78: =IFERROR(INDEX(#REF!,19),"")
A79: =IFERROR(INDEX(#REF!,20),"")
A80: =IFERROR(INDEX(#REF!,21),"")
A81: =IFERROR(INDEX(#REF!,22),"")
A82: =IFERROR(INDEX(#REF!,23),"")
A83: =IFERROR(INDEX(#REF!,24),"")
A84: =IFERROR(INDEX(#REF!,25),"")
A85: =IFERROR(INDEX(#REF!,26),"")
A86: =IFERROR(INDEX(#REF!,27),"")
A87: =IFERROR(INDEX(#REF!,28),"")
A88: =IFERROR(INDEX(#REF!,29),"")
A89: =IFERROR(INDEX(#REF!,30),"")
A92: Projet | B92: Materiels affectes | D92: Statut | E92: Nb
A93: =IFERROR(INDEX(#REF!,1),"") | B93: =IF(A93="","",COUNTIFS(#REF!,A93,#REF!,"")) | D93: Affecte | E93: =COUNTIF(#REF!,"Affecte") -> #REF!
A94: =IFERROR(INDEX(#REF!,2),"") | B94: =IF(A94="","",COUNTIFS(#REF!,A94,#REF!,"")) | D94: Disponible | E94: =COUNTIF(#REF!,"Disponible") -> #REF!
...

Sheet Base_Articles
A1: BASE ARTICLES - CATALOGUE UNIQUE (FTTH / GSM / BTP)
A2: Hypotheses : Stock Initial = stock net constate dans le fichier d'origine (deja net des entrees/sorties historiques). Seuils Stock Min/Max calcules par defaut (Min = 20% du stock, Max = 150% du stock) - a ajuster selon vos besoins reels. Prix unitaire absent du fichier source : saisir en colonne J (cellules bleues).
A4: Code Article | B4: Famille | C4: Designation | D4: Unite | E4: Fournisseur habituel | F4: Emplacement | G4: Stock Min | H4: Stock Max | I4: Stock Securite | J4: Prix Unitaire (FCFA) | K4: Stock Initial | L4: Qte Commandee | M4: Statut | N4: Date Creation | O4: Observation
A5: FO-0001 | B5: FO | C5: Boucle feuillard inox 20x0,7mm | D5: Piece | F5: Magasin Bureau | G5: 45 | H5: 340 | I5: 22 | J5: 0 | K5: 227 | L5: 0 | M5: Actif | N5: 46217
A6: FO-0002 | B6: FO | C6: Collier blanc petit | D6: Piece | F6: Magasin Bureau | G6: 5 | H6: 50 | I6: 2 | J6: 0 | K6: 0 | L6: 0 | M6: Actif | N6: 46217
A7: FO-0003 | B7: FO | C7: Dispositif de suspension JHC10-15 | D7: Piece | F7: Magasin Bureau | G7: 5 | H7: 50 | I7: 2 | J7: 0 | K7: 0 | L7: 0 | M7: Actif | N7: 46217
A8: FO-0004 | B8: FO | C8: Dispositif de suspension JHC15-20 | D8: Piece | F8: Magasin Bureau | G8: 5 | H8: 50 | I8: 2 | J8: 0 | K8: 0 | L8: 0 | M8: Actif | N8: 46217
A9: FO-0005 | B9: FO | C9: Embase cheville de 8 | D9: Piece | F9: Magasin Bureau | G9: 295 | H9: 2212 | I9: 148 | J9: 0 | K9: 1475 | L9: 0 | M9: Actif | N9: 46217
A10: FO-0006 | B10: FO | C10: Entraxe 5/33 | D10: Piece | F10: Magasin Bureau | G10: 5 | H10: 50 | I10: 2 | J10: 0 | K10: 0 | L10: 0 | M10: Actif | N10: 46217
A11: FO-0007 | B11: FO | C11: Feuillard inox 20x0,7 (rl 50m) | D11: Piece | F11: Magasin Bureau | G11: 5 | H11: 50 | I11: 2 | J11: 0 | K11: 1 | L11: 0 | M11: Actif | N11: 46217
A12: FO-0008 | B12: FO | C12: End box 2 core | D12: Piece | F12: Magasin Bureau | G12: 5 | H12: 50 | I12: 2 | J12: 0 | K12: 0 | L12: 0 | M12: Actif | N12: 46217
A13: FO-0009 | B13: FO | C13: Pince d'ancrage FO ADSS6-8 | D13: Piece | F13: Magasin Bureau | G13: 28 | H13: 210 | I13: 14 | J13: 0 | K13: 140 | L13: 0 | M13: Actif | N13: 46217
A14: FO-0010 | B14: FO | C14: Pince d'ancrage FO ADSS12 | D14: Piece | F14: Magasin Bureau | G14: 5 | H14: 50 | I14: 2 | J14: 0 | K14: 0 | L14: 0 | M14: Actif | N14: 46217
A15: FO-0011 | B15: FO | C15: Pince d'ancrage FO ADSS6 | D15: Piece | F15: Magasin Bureau | G15: 5 | H15: 50 | I15: 2 | J15: 0 | K15: 0 | L15: 0 | M15: Actif | N15: 46217
A16: FO-0012 | B16: FO | C16: Semelle à goupille | D16: Piece | F16: Magasin Bureau | G16: 5 | H16: 50 | I16: 2 | J16: 0 | K16: 0 | L16: 0 | M16: Actif | N16: 46217
... A208: BLR-0009 | B208: BLR | C208: Bombe galva | D208: Piece | F208: Magasin Bureau | G208: 5 | H208: 50 | I208: 2 | J208: 0 | K208: 0 | L208: 0 | M208: Actif | N208: 46217
A209: NEW-0001 | B209: BLR (a classer) | C209: Bombe à air sèc | D209: Piece | F209: Magasin Bureau | G209: 5 | H209: 50 | I209: 2 | J209: 0 | K209: 0 | L209: 0 | M209: Actif | N209: 46217 | O209: Nouvel article signale - inventaire physique a realiser
A210: NEW-0002 | B210: BLR (a classer) | C210: Meplat 30x2mm | D210: Piece | F210: Magasin Bureau | G210: 5 | H210: 50 | I210: 2 | J210: 0 | K210: 0 | L210: 0 | M210: Actif | N210: 46217 | O210: Nouvel article signale - inventaire physique a realiser
A211: NEW-0003 | B211: BLR (a classer) | C211: Barette de terre 8 trous | D211: Piece | F211: Magasin Bureau | G211: 5 | H211: 50 | I211: 2 | J211: 0 | K211: 0 | L211: 0 | M211: Actif | N211: 46217 | O211: Nouvel article signale - inventaire physique a realiser
A212: NEW-0004 | B212: BLR (a classer) | C212: câble parafoudre | D212: Piece | F212: Magasin Bureau | G212: 5 | H212: 50 | I212: 2 | J212: 0 | K212: 0 | L212: 0 | M212: Actif | N212: 46217 | O212: Nouvel article signale - inventaire physique a realiser
A213: NEW-0005 | B213: BLR (a classer) | C213: Regard de visite | D213: Piece | F213: Magasin Bureau | G213: 5 | H213: 50 | I213: 2 | J213: 0 | K213: 0 | L213: 0 | M213: Actif | N213: 46217 | O213: Nouvel article signale - inventaire physique a realiser
A214: NEW-0006 | B214: BLR (a classer) | C214: Attache meplat | D214: Piece | F214: Magasin Bureau | G214: 5 | H214: 50 | I214: 2 | J214: 0 | K214: 0 | L214: 0 | M214: Actif | N214: 46217 | O214: Nouvel article signale - inventaire physique a realiser
A215: NEW-0007 | B215: BLR (a classer) | C215: Bitume cargot | D215: Piece | F215: Magasin Bureau | G215: 5 | H215: 50 | I215: 2 | J215: 0 | K215: 0 | L215: 0 | M215: Actif | N215: 46217 | O215: Nouvel article signale - inventaire physique a realiser
A216: NEW-0008 | B216: BLR (a classer) | C216: Tendeur fil barbélé | D216: Piece | F216: Magasin Bureau | G216: 5 | H216: 50 | I216: 2 | J216: 0 | K216: 0 | L216: 0 | M216: Actif | N216: 46217 | O216: Nouvel article signale - inventaire physique a realiser
A217: NEW-0009 | B217: BLR (a classer) | C217: Manchon | D217: Piece | F217: Magasin Bureau | G217: 5 | H217: 50 | I217: 2 | J217: 0 | K217: 0 | L217: 0 | M217: Actif | N217: 46217 | O217: Nouvel article signale - inventaire physique a realiser
A218: NEW-0010 | B218: BLR (a classer) | C218: Silicone | D218: Piece | F218: Magasin Bureau | G218: 5 | H218: 50 | I218: 2 | J218: 0 | K218: 0 | L218: 0 | M218: Actif | N218: 46217 | O218: Nouvel article signale - inventaire physique a realiser

Sheet Entrees
A1: ENTREES DE MATERIEL
A2: Les mouvements historiques (janvier 2026) sont deja integres dans le Stock Initial de la Base Articles (voir feuille Historique_Import_2026 pour le detail brut). Enregistrez ici uniquement les NOUVELLES entrees.
A4: Date | B4: N Bon | C4: Code Article | D4: Designation | E4: Fournisseur | F4: Projet | G4: Magasin | H4: Responsable | I4: Quantite | J4: Prix Unitaire | K4: Montant | L4: Observation | M4: Code Projet
A5: 46035 | B5: EXEMPLE | C5: EX-0000 | D5: =IFERROR(INDEX(#REF!,MATCH(C5,#REF!,0)),"") | E5: OUMAR | F5: FTTH | G5: Magasin Bureau | H5: URIEL | I5: 10 | J5: 0 | K5: =IF(AND(I5<>"",J5<>""),I5*J5,"") -> 0 | L5: Ligne d'exemple - a supprimer ou modifier
D6: =IFERROR(INDEX(#REF!,MATCH(C6,#REF!,0)),"") | K6: =IF(AND(I6<>"",J6<>""),I6*J6,"")
D7: =IFERROR(INDEX(#REF!,MATCH(C7,#REF!,0)),"") | K7: =IF(AND(I7<>"",J7<>""),I7*J7,"")
D8: =IFERROR(INDEX(#REF!,MATCH(C8,#REF!,0)),"") | K8: =IF(AND(I8<>"",J8<>""),I8*J8,"")
D9: =IFERROR(INDEX(#REF!,MATCH(C9,#REF!,0)),"") | K9: =IF(AND(I9<>"",J9<>""),I9*J9,"")
D10: =IFERROR(INDEX(#REF!,MATCH(C10,#REF!,0)),"") | K10: =IF(AND(I10<>"",J10<>""),I10*J10,"")
D11: =IFERROR(INDEX(#REF!,MATCH(C11,#REF!,0)),"") | K11: =IF(AND(I11<>"",J11<>""),I11*J11,"")
D12: =IFERROR(INDEX(#REF!,MATCH(C12,#REF!,0)),"") | K12: =IF(AND(I12<>"",J12<>""),I12*J12,"")
D13: =IFERROR(INDEX(#REF!,MATCH(C13,#REF!,0)),"") | K13: =IF(AND(I13<>"",J13<>""),I13*J13,"")
D14: =IFERROR(INDEX(#REF!,MATCH(C14,#REF!,0)),"") | K14: =IF(AND(I14<>"",J14<>""),I14*J14,"")
D15: =IFERROR(INDEX(#REF!,MATCH(C15,#REF!,0)),"") | K15: =IF(AND(I15<>"",J15<>""),I15*J15,"")
D16: =IFERROR(INDEX(#REF!,MATCH(C16,#REF!,0)),"") | K16: =IF(AND(I16<>"",J16<>""),I16*J16,"")
D17: =IFERROR(INDEX(#REF!,MATCH(C17,#REF!,0)),"") | K17: =IF(AND(I17<>"",J17<>""),I17*J17,"")
... D64: =IFERROR(INDEX(#REF!,MATCH(C64,#REF!,0)),"") | K64: =IF(AND(I64<>"",J64<>""),I64*J64,"")

Sheet Sorties
A1: SORTIES DE MATERIEL
A2: Enregistrez ici chaque sortie de materiel (chantier, employe, projet).
A4: Date | B4: N Bon Sortie | C4: Code Article | D4: Designation | E4: Employe | F4: Departement | G4: Chantier | H4: Responsable | I4: Quantite | J4: Destination | K4: Motif | L4: Observation | M4: Code Projet
A5: 46036 | B5: EXEMPLE | C5: EX-0000 | D5: =IFERROR(INDEX(#REF!,MATCH(C5,#REF!,0)),"") | E5: Technicien A | F5: FTTH | G5: Site Cite Cephal | H5: URIEL | I5: 5 | J5: Chantier | K5: Deploiement | L5: Ligne d'exemple - a supprimer ou modifier
D6: =IFERROR(INDEX(#REF!,MATCH(C6,#REF!,0)),"")
D7: =IFERROR(INDEX(#REF!,MATCH(C7,#REF!,0)),"")
D8: =IFERROR(INDEX(#REF!,MATCH(C8,#REF!,0)),"")
D9: =IFERROR(INDEX(#REF!,MATCH(C9,#REF!,0)),"")
D10: =IFERROR(INDEX(#REF!,MATCH(C10,#REF!,0)),"")
D11: =IFERROR(INDEX(#REF!,MATCH(C11,#REF!,0)),"")
D12: =IFERROR(INDEX(#REF!,MATCH(C12,#REF!,0)),"")
D13: =IFERROR(INDEX(#REF!,MATCH(C13,#REF!,0)),"")
D14: =IFERROR(INDEX(#REF!,MATCH(C14,#REF!,0)),"")
D15: =IFERROR(INDEX(#REF!,MATCH(C15,#REF!,0)),"")
D16: =IFERROR(INDEX(#REF!,MATCH(C16,#REF!,0)),"")
D17: =IFERROR(INDEX(#REF!,MATCH(C17,#REF!,0)),"")
... D64: =IFERROR(INDEX(#REF!,MATCH(C64,#REF!,0)),"")

Sheet Stock_TempsReel
A1: STOCK EN TEMPS REEL
A4: Code Article | B4: Designation | C4: Famille | D4: Stock Initial | E4: Entrees cumulees | F4: Sorties cumulees | G4: Stock Actuel | H4: Stock Min | I4: Stock Max | J4: Prix Unitaire | K4: Valeur Stock (FCFA) | L4: Statut
A5: =Base_Articles!A5 -> FO-0001 | B5: =Base_Articles!C5 -> Boucle feuillard inox 20x0,7mm | C5: =Base_Articles!B5 -> FO | D5: =Base_Articles!K5 -> 227 | E5: =SUMIFS(#REF!,#REF!,A5) -> #REF! | F5: =SUMIFS(#REF!,#REF!,A5) -> #REF! | G5: =D5+E5-F5 -> #REF! | H5: =Base_Articles!G5 -> 45 | I5: =Base_Articles!H5 -> 340 | J5: =Base_Articles!J5 -> 0 | K5: =G5*J5 -> #REF! | L5: =IF(G5<=0,"RUPTURE",IF(G5<=H5,"CRITIQUE",IF(G5>I5,"SURSTOCK","DISPONIBLE"))) -> #REF!
A6: =Base_Articles!A6 -> FO-0002 | B6: =Base_Articles!C6 -> Collier blanc petit | C6: =Base_Articles!B6 -> FO | D6: =Base_Articles!K6 -> 0 | E6: =SUMIFS(#REF!,#REF!,A6) -> #REF! | F6: =SUMIFS(#REF!,#REF!,A6) -> #REF! | G6: =D6+E6-F6 -> #REF! | H6: =Base_Articles!G6 -> 5 | I6: =Base_Articles!H6 -> 50 | J6: =Base_Articles!J6 -> 0 | K6: =G6*J6 -> #REF! | L6: =IF(G6<=0,"RUPTURE",IF(G6<=H6,"CRITIQUE",IF(G6>I6,"SURSTOCK","DISPONIBLE"))) -> #REF!
A7: =Base_Articles!A7 -> FO-0003 | B7: =Base_Articles!C7 -> Dispositif de suspension JHC10-15 | C7: =Base_Articles!B7 -> FO | D7: =Base_Articles!K7 -> 0 | E7: =SUMIFS(#REF!,#REF!,A7) -> #REF! | F7: =SUMIFS(#REF!,#REF!,A7) -> #REF! | G7: =D7+E7-F7 -> #REF! | H7: =Base_Articles!G7 -> 5 | I7: =Base_Articles!H7 -> 50 | J7: =Base_Articles!J7 -> 0 | K7: =G7*J7 -> #REF! | L7: =IF(G7<=0,"RUPTURE",IF(G7<=H7,"CRITIQUE",IF(G7>I7,"SURSTOCK","DISPONIBLE"))) -> #REF!
A8: =Base_Articles!A8 -> FO-0004 | B8: =Base_Articles!C8 -> Dispositif de suspension JHC15-20 | C8: =Base_Articles!B8 -> FO | D8: =Base_Articles!K8 -> 0 | E8: =SUMIFS(#REF!,#REF!,A8) -> #REF! | F8: =SUMIFS(#REF!,#REF!,A8) -> #REF! | G8: =D8+E8-F8 -> #REF! | H8: =Base_Articles!G8 -> 5 | I8: =Base_Articles!H8 -> 50 | J8: =Base_Articles!J8 -> 0 | K8: =G8*J8 -> #REF! | L8: =IF(G8<=0,"RUPTURE",IF(G8<=H8,"CRITIQUE",IF(G8>I8,"SURSTOCK","DISPONIBLE"))) -> #REF!
A9: =Base_Articles!A9 -> FO-0005 | B9: =Base_Articles!C9 -> Embase cheville de 8 | C9: =Base_Articles!B9 -> FO | D9: =Base_Articles!K9 -> 1475 | E9: =SUMIFS(#REF!,#REF!,A9) -> #REF! | F9: =SUMIFS(#REF!,#REF!,A9) -> #REF! | G9: =D9+E9-F9 -> #REF! | H9: =Base_Articles!G9 -> 295 | I9: =Base_Articles!H9 -> 2212 | J9: =Base_Articles!J9 -> 0 | K9: =G9*J9 -> #REF! | L9: =IF(G9<=0,"RUPTURE",IF(G9<=H9,"CRITIQUE",IF(G9>I9,"SURSTOCK","DISPONIBLE"))) -> #REF!
A10: =Base_Articles!A10 -> FO-0006 | B10: =Base_Articles!C10 -> Entraxe 5/33 | C10: =Base_Articles!B10 -> FO | D10: =Base_Articles!K10 -> 0 | E10: =SUMIFS(#REF!,#REF!,A10) -> #REF! | F10: =SUMIFS(#REF!,#REF!,A10) -> #REF! | G10: =D10+E10-F10 -> #REF! | H10: =Base_Articles!G10 -> 5 | I10: =Base_Articles!H10 -> 50 | J10: =Base_Articles!J10 -> 0 | K10: =G10*J10 -> #REF! | L10: =IF(G10<=0,"RUPTURE",IF(G10<=H10,"CRITIQUE",IF(G10>I10,"SURSTOCK","DISPONIBLE"))) -> #REF!
A11: =Base_Articles!A11 -> FO-0007 | B11: =Base_Articles!C11 -> Feuillard inox 20x0,7 (rl 50m) | C11: =Base_Articles!B11 -> FO | D11: =Base_Articles!K11 -> 1 | E11: =SUMIFS(#REF!,#REF!,A11) -> #REF! | F11: =SUMIFS(#REF!,#REF!,A11) -> #REF! | G11: =D11+E11-F11 -> #REF! | H11: =Base_Articles!G11 -> 5 | I11: =Base_Articles!H11 -> 50 | J11: =Base_Articles!J11 -> 0 | K11: =G11*J11 -> #REF! | L11: =IF(G11<=0,"RUPTURE",IF(G11<=H11,"CRITIQUE",IF(G11>I11,"SURSTOCK","DISPONIBLE"))) -> #REF!
A12: =Base_Articles!A12 -> FO-0008 | B12: =Base_Articles!C12 -> End box 2 core | C12: =Base_Articles!B12 -> FO | D12: =Base_Articles!K12 -> 0 | E12: =SUMIFS(#REF!,#REF!,A12) -> #REF! | F12: =SUMIFS(#REF!,#REF!,A12) -> #REF! | G12: =D12+E12-F12 -> #REF! | H12: =Base_Articles!G12 -> 5 | I12: =Base_Articles!H12 -> 50 | J12: =Base_Articles!J12 -> 0 | K12: =G12*J12 -> #REF! | L12: =IF(G12<=0,"RUPTURE",IF(G12<=H12,"CRITIQUE",IF(G12>I12,"SURSTOCK","DISPONIBLE"))) -> #REF!
A13: =Base_Articles!A13 -> FO-0009 | B13: =Base_Articles!C13 -> Pince d'ancrage FO ADSS6-8 | C13: =Base_Articles!B13 -> FO | D13: =Base_Articles!K13 -> 140 | E13: =SUMIFS(#REF!,#REF!,A13) -> #REF! | F13: =SUMIFS(#REF!,#REF!,A13) -> #REF! | G13: =D13+E13-F13 -> #REF! | H13: =Base_Articles!G13 -> 28 | I13: =Base_Articles!H13 -> 210 | J13: =Base_Articles!J13 -> 0 | K13: =G13*J13 -> #REF! | L13: =IF(G13<=0,"RUPTURE",IF(G13<=H13,"CRITIQUE",IF(G13>I13,"SURSTOCK","DISPONIBLE"))) -> #REF!
A14: =Base_Articles!A14 -> FO-0010 | B14: =Base_Articles!C14 -> Pince d'ancrage FO ADSS12 | C14: =Base_Articles!B14 -> FO | D14: =Base_Articles!K14 -> 0 | E14: =SUMIFS(#REF!,#REF!,A14) -> #REF! | F14: =SUMIFS(#REF!,#REF!,A14) -> #REF! | G14: =D14+E14-F14 -> #REF! | H14: =Base_Articles!G14 -> 5 | I14: =Base_Articles!H14 -> 50 | J14: =Base_Articles!J14 -> 0 | K14: =G14*J14 -> #REF! | L14: =IF(G14<=0,"RUPTURE",IF(G14<=H14,"CRITIQUE",IF(G14>I14,"SURSTOCK","DISPONIBLE"))) -> #REF!
A15: =Base_Articles!A15 -> FO-0011 | B15: =Base_Articles!C15 -> Pince d'ancrage FO ADSS6 | C15: =Base_Articles!B15 -> FO | D15: =Base_Articles!K15 -> 0 | E15: =SUMIFS(#REF!,#REF!,A15) -> #REF! | F15: =SUMIFS(#REF!,#REF!,A15) -> #REF! | G15: =D15+E15-F15 -> #REF! | H15: =Base_Articles!G15 -> 5 | I15: =Base_Articles!H15 -> 50 | J15: =Base_Articles!J15 -> 0 | K15: =G15*J15 -> #REF! | L15: =IF(G15<=0,"RUPTURE",IF(G15<=H15,"CRITIQUE",IF(G15>I15,"SURSTOCK","DISPONIBLE"))) -> #REF!
A16: =Base_Articles!A16 -> FO-0012 | B16: =Base_Articles!C16 -> Semelle à goupille | C16: =Base_Articles!B16 -> FO | D16: =Base_Articles!K16 -> 0 | E16: =SUMIFS(#REF!,#REF!,A16) -> #REF! | F16: =SUMIFS(#REF!,#REF!,A16) -> #REF! | G16: =D16+E16-F16 -> #REF! | H16: =Base_Articles!G16 -> 5 | I16: =Base_Articles!H16 -> 50 | J16: =Base_Articles!J16 -> 0 | K16: =G16*J16 -> #REF! | L16: =IF(G16<=0,"RUPTURE",IF(G16<=H16,"CRITIQUE",IF(G16>I16,"SURSTOCK","DISPONIBLE"))) -> #REF!
... A218: =Base_Articles!A218 -> NEW-0010 | B218: =Base_Articles!C218 -> Silicone | C218: =Base_Articles!B218 -> BLR (a classer) | D218: =Base_Articles!K218 -> 0 | E218: =SUMIFS(#REF!,#REF!,A218) -> #REF! | F218: =SUMIFS(#REF!,#REF!,A218) -> #REF! | G218: =D218+E218-F218 -> #REF! | H218: =Base_Articles!G218 -> 5 | I218: =Base_Articles!H218 -> 50 | J218: =Base_Articles!J218 -> 0 | K218: =G218*J218 -> #REF! | L218: =IF(G218<=0,"RUPTURE",IF(G218<=H218,"CRITIQUE",IF(G218>I218,"SURSTOCK","DISPONIBLE"))) -> #REF!

Sheet Equipements
A1: GESTION DES EQUIPEMENTS ET OUTILS
A4: Code Inventaire | B4: Designation | C4: Quantite | D4: Marque | E4: Numero de serie | F4: Etat | G4: Employe affecte | H4: Localisation | I4: Date achat | J4: Garantie jusqu au | K4: Observation | L4: Dernier Mouvement (date) | M4: Projet Actuel | N4: Statut Actuel (Tracabilite) | O4: Jours Depuis Dernier Mouvement
A5: EQ-001 | B5: Imprimante | C5: 1 | F5: Disponible | H5: Depot Bureau | L5: =IF(COUNTIFS(#REF!,A5)=0,"",_xlfn.MAXIFS(#REF!,#REF!,A5)) -> #REF! | M5: =IFERROR(INDEX(#REF!,MATCH(A5&"|"&TEXT(L5,"YYYYMMDD"),#REF!,0)),"") | N5: =IF(L5="","Disponible (aucun mouvement)",IFERROR(INDEX(#REF!,MATCH(A5&"|"&TEXT(L5,"YYYYMMDD"),#REF!,0)),"Disponible")) -> #REF! | O5: =IF(L5<>"",TODAY()-L5,"") -> #REF!
A6: EQ-002 | B6: Ruban de balisage | C6: 3 | F6: Disponible | H6: Depot Bureau | L6: =IF(COUNTIFS(#REF!,A6)=0,"",_xlfn.MAXIFS(#REF!,#REF!,A6)) -> #REF! | M6: =IFERROR(INDEX(#REF!,MATCH(A6&"|"&TEXT(L6,"YYYYMMDD"),#REF!,0)),"") | N6: =IF(L6="","Disponible (aucun mouvement)",IFERROR(INDEX(#REF!,MATCH(A6&"|"&TEXT(L6,"YYYYMMDD"),#REF!,0)),"Disponible")) -> #REF! | O6: =IF(L6<>"",TODAY()-L6,"") -> #REF!
A7: EQ-003 | B7: Projecteur | C7: 2 | F7: Disponible | H7: Depot Bureau | L7: =IF(COUNTIFS(#REF!,A7)=0,"",_xlfn.MAXIFS(#REF!,#REF!,A7)) -> #REF! | M7: =IFERROR(INDEX(#REF!,MATCH(A7&"|"&TEXT(L7,"YYYYMMDD"),#REF!,0)),"") | N7: =IF(L7="","Disponible (aucun mouvement)",IFERROR(INDEX(#REF!,MATCH(A7&"|"&TEXT(L7,"YYYYMMDD"),#REF!,0)),"Disponible")) -> #REF! | O7: =IF(L7<>"",TODAY()-L7,"") -> #REF!
A8: EQ-004 | B8: Powermeter | C8: 0 | F8: Disponible | H8: Depot Bureau | L8: =IF(COUNTIFS(#REF!,A8)=0,"",_xlfn.MAXIFS(#REF!,#REF!,A8)) -> #REF! | M8: =IFERROR(INDEX(#REF!,MATCH(A8&"|"&TEXT(L8,"YYYYMMDD"),#REF!,0)),"") | N8: =IF(L8="","Disponible (aucun mouvement)",IFERROR(INDEX(#REF!,MATCH(A8&"|"&TEXT(L8,"YYYYMMDD"),#REF!,0)),"Disponible")) -> #REF! | O8: =IF(L8<>"",TODAY()-L8,"") -> #REF!
A9: EQ-005 | B9: Niveau 60cm | C9: 1 | F9: Disponible | H9: Depot Bureau | L9: =IF(COUNTIFS(#REF!,A9)=0,"",_xlfn.MAXIFS(#REF!,#REF!,A9)) -> #REF! | M9: =IFERROR(INDEX(#REF!,MATCH(A9&"|"&TEXT(L9,"YYYYMMDD"),#REF!,0)),"") | N9: =IF(L9="","Disponible (aucun mouvement)",IFERROR(INDEX(#REF!,MATCH(A9&"|"&TEXT(L9,"YYYYMMDD"),#REF!,0)),"Disponible")) -> #REF! | O9: =IF(L9<>"",TODAY()-L9,"") -> #REF!
A10: EQ-006 | B10: Detecteur de metaux | C10: 1 | F10: Disponible | H10: Depot Bureau | L10: =IF(COUNTIFS(#REF!,A10)=0,"",_xlfn.MAXIFS(#REF!,#REF!,A10)) -> #REF! | M10: =IFERROR(INDEX(#REF!,MATCH(A10&"|"&TEXT(L10,"YYYYMMDD"),#REF!,0)),"") | N10: =IF(L10="","Disponible (aucun mouvement)",IFERROR(INDEX(#REF!,MATCH(A10&"|"&TEXT(L10,"YYYYMMDD"),#REF!,0)),"Disponible")) -> #REF! | O10: =IF(L10<>"",TODAY()-L10,"") -> #REF!
A11: EQ-007 | B11: Stickers | C11: 1 | F11: Disponible | H11: Depot Bureau | L11: =IF(COUNTIFS(#REF!,A11)=0,"",_xlfn.MAXIFS(#REF!,#REF!,A11)) -> #REF! | M11: =IFERROR(INDEX(#REF!,MATCH(A11&"|"&TEXT(L11,"YYYYMMDD"),#REF!,0)),"") | N11: =IF(L11="","Disponible (aucun mouvement)",IFERROR(INDEX(#REF!,MATCH(A11&"|"&TEXT(L11,"YYYYMMDD"),#REF!,0)),"Disponible")) -> #REF! | O11: =IF(L11<>"",TODAY()-L11,"") -> #REF!
A12: EQ-008 | B12: Cliveuse | C12: 1 | F12: Disponible | H12: Depot Bureau | L12: =IF(COUNTIFS(#REF!,A12)=0,"",_xlfn.MAXIFS(#REF!,#REF!,A12)) -> #REF! | M12: =IFERROR(INDEX(#REF!,MATCH(A12&"|"&TEXT(L12,"YYYYMMDD"),#REF!,0)),"") | N12: =IF(L12="","Disponible (aucun mouvement)",IFERROR(INDEX(#REF!,MATCH(A12&"|"&TEXT(L12,"YYYYMMDD"),#REF!,0)),"Disponible")) -> #REF! | O12: =IF(L12<>"",TODAY()-L12,"") -> #REF!
A13: EQ-009 | B13: Theodolite | C13: 1 | F13: Disponible | H13: Depot Bureau | L13: =IF(COUNTIFS(#REF!,A13)=0,"",_xlfn.MAXIFS(#REF!,#REF!,A13)) -> #REF! | M13: =IFERROR(INDEX(#REF!,MATCH(A13&"|"&TEXT(L13,"YYYYMMDD"),#REF!,0)),"") | N13: =IF(L13="","Disponible (aucun mouvement)",IFERROR(INDEX(#REF!,MATCH(A13&"|"&TEXT(L13,"YYYYMMDD"),#REF!,0)),"Disponible")) -> #REF! | O13: =IF(L13<>"",TODAY()-L13,"") -> #REF!
A14: EQ-010 | B14: Perceuse filaire | C14: 1 | F14: Disponible | H14: Depot Bureau | L14: =IF(COUNTIFS(#REF!,A14)=0,"",_xlfn.MAXIFS(#REF!,#REF!,A14)) -> #REF! | M14: =IFERROR(INDEX(#REF!,MATCH(A14&"|"&TEXT(L14,"YYYYMMDD"),#REF!,0)),"") | N14: =IF(L14="","Disponible (aucun mouvement)",IFERROR(INDEX(#REF!,MATCH(A14&"|"&TEXT(L14,"YYYYMMDD"),#REF!,0)),"Disponible")) -> #REF! | O14: =IF(L14<>"",TODAY()-L14,"") -> #REF!
A15: EQ-011 | B15: Caisse a outils | C15: 1 | F15: Disponible | H15: Depot Bureau | L15: =IF(COUNTIFS(#REF!,A15)=0,"",_xlfn.MAXIFS(#REF!,#REF!,A15)) -> #REF! | M15: =IFERROR(INDEX(#REF!,MATCH(A15&"|"&TEXT(L15,"YYYYMMDD"),#REF!,0)),"") | N15: =IF(L15="","Disponible (aucun mouvement)",IFERROR(INDEX(#REF!,MATCH(A15&"|"&TEXT(L15,"YYYYMMDD"),#REF!,0)),"Disponible")) -> #REF! | O15: =IF(L15<>"",TODAY()-L15,"") -> #REF!
A16: EQ-012 | B16: Mallette a outils | C16: 1 | F16: Disponible | H16: Depot Bureau | L16: =IF(COUNTIFS(#REF!,A16)=0,"",_xlfn.MAXIFS(#REF!,#REF!,A16)) -> #REF! | M16: =IFERROR(INDEX(#REF!,MATCH(A16&"|"&TEXT(L16,"YYYYMMDD"),#REF!,0)),"") | N16: =IF(L16="","Disponible (aucun mouvement)",IFERROR(INDEX(#REF!,MATCH(A16&"|"&TEXT(L16,"YYYYMMDD"),#REF!,0)),"Disponible")) -> #REF! | O16: =IF(L16<>"",TODAY()-L16,"") -> #REF!
... A41: EQ-037 | B41: Soudeuse FO n7 | C41: 1 | F41: Disponible | H41: Depot Bureau | L41: =IF(COUNTIFS(#REF!,A41)=0,"",_xlfn.MAXIFS(#REF!,#REF!,A41)) -> #REF! | M41: =IFERROR(INDEX(#REF!,MATCH(A41&"|"&TEXT(L41,"YYYYMMDD"),#REF!,0)),"") | N41: =IF(L41="","Disponible (aucun mouvement)",IFERROR(INDEX(#REF!,MATCH(A41&"|"&TEXT(L41,"YYYYMMDD"),#REF!,0)),"Disponible")) -> #REF! | O41: =IF(L41<>"",TODAY()-L41,"") -> #REF!

Sheet Projets
A1: FICHE PROJETS / CHANTIERS
A2: Une ligne = un projet/chantier. Cree la fiche ici avant d'enregistrer des affectations de materiel dans la feuille Affectations (les listes deroulantes de cette derniere se basent sur cette liste).
A4: Code Projet | B4: Nom du Projet | C4: Client | D4: Region | E4: Ville | F4: Chantier | G4: Chef de Projet | H4: Conducteur des Travaux | I4: Responsable Logistique | J4: Societe Sous-traitante | K4: Budget Materiel Alloue (FCFA) | L4: Date Debut | M4: Date Fin Prevue | N4: Statut Projet | O4: Nb Equip. Actuellement Affectes | P4: Consommables Sortis (Qte) | Q4: Observation
A5: PRJ-0001 | B5: MTN - Site Yopougon PK18 | C5: MTN | D5: Abidjan | E5: Yopougon | F5: Site GSM PK18 | G5: A definir | H5: A definir | I5: A definir | K5: 0 | L5: 46023 | N5: Actif | O5: =COUNTIFS(#REF!,B5,#REF!,"") -> #REF! | P5: =IFERROR(SUMIFS(#REF!,#REF!,A5),0) -> 0 | Q5: EXEMPLE - a completer / dupliquer
A6: PRJ-0002 | B6: Orange - Backbone Bouake | C6: Orange | D6: Bouake | E6: Bouake | F6: Liaison Backbone | G6: A definir | H6: A definir | I6: A definir | K6: 0 | L6: 46023 | N6: Actif | O6: =COUNTIFS(#REF!,B6,#REF!,"") -> #REF! | P6: =IFERROR(SUMIFS(#REF!,#REF!,A6),0) -> 0 | Q6: EXEMPLE - a completer / dupliquer
A7: PRJ-0003 | B7: Moov Africa - Site Korhogo | C7: Moov Africa | D7: Korhogo | E7: Korhogo | F7: Site GSM Korhogo | G7: A definir | H7: A definir | I7: A definir | K7: 0 | L7: 46023 | N7: Actif | O7: =COUNTIFS(#REF!,B7,#REF!,"") -> #REF! | P7: =IFERROR(SUMIFS(#REF!,#REF!,A7),0) -> 0 | Q7: EXEMPLE - a completer / dupliquer
O8: =COUNTIFS(#REF!,B8,#REF!,"") -> #REF! | P8: =IFERROR(SUMIFS(#REF!,#REF!,A8),0) -> 0
O9: =COUNTIFS(#REF!,B9,#REF!,"") -> #REF! | P9: =IFERROR(SUMIFS(#REF!,#REF!,A9),0) -> 0
O10: =COUNTIFS(#REF!,B10,#REF!,"") -> #REF! | P10: =IFERROR(SUMIFS(#REF!,#REF!,A10),0) -> 0
O11: =COUNTIFS(#REF!,B11,#REF!,"") -> #REF! | P11: =IFERROR(SUMIFS(#REF!,#REF!,A11),0) -> 0
O12: =COUNTIFS(#REF!,B12,#REF!,"") -> #REF! | P12: =IFERROR(SUMIFS(#REF!,#REF!,A12),0) -> 0
O13: =COUNTIFS(#REF!,B13,#REF!,"") -> #REF! | P13: =IFERROR(SUMIFS(#REF!,#REF!,A13),0) -> 0
O14: =COUNTIFS(#REF!,B14,#REF!,"") -> #REF! | P14: =IFERROR(SUMIFS(#REF!,#REF!,A14),0) -> 0
O15: =COUNTIFS(#REF!,B15,#REF!,"") -> #REF! | P15: =IFERROR(SUMIFS(#REF!,#REF!,A15),0) -> 0
O16: =COUNTIFS(#REF!,B16,#REF!,"") -> #REF! | P16: =IFERROR(SUMIFS(#REF!,#REF!,A16),0) -> 0
O17: =COUNTIFS(#REF!,B17,#REF!,"") -> #REF! | P17: =IFERROR(SUMIFS(#REF!,#REF!,A17),0) -> 0
O18: =COUNTIFS(#REF!,B18,#REF!,"") -> #REF! | P18: =IFERROR(SUMIFS(#REF!,#REF!,A18),0) -> 0
O19: =COUNTIFS(#REF!,B19,#REF!,"") -> #REF! | P19: =IFERROR(SUMIFS(#REF!,#REF!,A19),0) -> 0
... O34: =COUNTIFS(#REF!,B34,#REF!,"") -> #REF! | P34: =IFERROR(SUMIFS(#REF!,#REF!,A34),0) -> 0

Sheet Affectations
A1: AFFECTATIONS & TRACABILITE DU MATERIEL
A2: Chaque ligne = un mouvement de materiel (sortie, transfert, retour). L'historique complet d'un equipement s'obtient en filtrant la colonne Code Materiel. Le Statut et le flag Retard sont calcules automatiquement. Colonnes grisees = calculees automatiquement, ne pas modifier.
A4: N Mouvement | B4: Date Sortie | C4: Projet | D4: Code Projet | E4: Client | F4: Region | G4: Ville | H4: Chantier | I4: Chef de Projet | J4: Conducteur des Travaux | K4: Responsable Logistique | L4: Employe Beneficiaire | M4: Societe Sous-traitante | N4: Magasin de Depart | O4: Code Materiel | P4: Designation | Q4: Numero de Serie | R4: QR Code | S4: Quantite | T4: Etat avant sortie | U4: Etat au retour | V4: Date retour prevue | W4: Date reelle retour | X4: Jours d'utilisation | Y4: Observation | Z4: Signature electronique | AA4: Statut | AB4: Retard | AC4: Cle | AD4: Rang Materiel | AE4: Cle Rang | AF4: Rang Retard | AG4: Cle Retard | AH4: Anomalie Double Affectation
A5: ="MVT-"&TEXT(ROW()-4,"0000") -> MVT-0001 | B5: 46042 | C5: MTN - Site Yopougon PK18 | D5: =IFERROR(INDEX(#REF!,MATCH(C5,#REF!,0)),"") | E5: =IFERROR(INDEX(#REF!,MATCH(C5,#REF!,0)),"") | F5: =IFERROR(INDEX(#REF!,MATCH(C5,#REF!,0)),"") | G5: =IFERROR(INDEX(#REF!,MATCH(C5,#REF!,0)),"") | H5: =IFERROR(INDEX(#REF!,MATCH(C5,#REF!,0)),"") | I5: =IFERROR(INDEX(#REF!,MATCH(C5,#REF!,0)),"") | J5: =IFERROR(INDEX(#REF!,MATCH(C5,#REF!,0)),"") | K5: =IFERROR(INDEX(#REF!,MATCH(C5,#REF!,0)),"") | L5: Technicien EXEMPLE | N5: Magasin Bureau | O5: EX-0000 | P5: =IFERROR(INDEX(#REF!,MATCH(O5,#REF!,0)),"") | Q5: =IFERROR(INDEX(#REF!,MATCH(O5,#REF!,0)),"") | R5: =O5 -> EX-0000 | S5: 1 | T5: Disponible | V5: 46073 | X5: =IF(W5<>"",W5-B5,IF(B5<>"",TODAY()-B5,"")) -> 191 | Y5: Ligne d'exemple - a supprimer ou modifier | AA5: =IF(O5="","",IF(W5<>"",IF(OR(U5="Perdu",U5="Vole",U5="Reforme",U5="En maintenance",U5="En reparation"),U5,"Disponible"),IF(AND(V5<>"",TODAY()>V5),"En retard","Affecte"))) -> En retard | AB5: =IF(AND(O5<>"",W5="",V5<>"",TODAY()>V5),"OUI","NON") -> OUI | AC5: =IF(O5<>"",O5&"|"&TEXT(B5,"YYYYMMDD"),"") -> EX-0000|20260120 | AD5: =IF(O5<>"",COUNTIFS($O$5:O5,O5),"") -> 1 | AE5: =IF(O5<>"",O5&"|R"&AD5,"") -> EX-0000|R1 | AF5: =IF(AB5="OUI",COUNTIFS($AB$5:AB5,"OUI"),"") -> 1 | AG5: =IF(AB5="OUI","RETARD|R"&AF5,"") -> RETARD|R1 | AH5: =IF(AND(O5<>"",W5=""),IF(COUNTIFS($O$5:$O$84,O5,$W$5:$W$84,"")>1,"OUI","NON"),"NON") -> NON
A6: ="MVT-"&TEXT(ROW()-4,"0000") -> MVT-0002 | D6: =IFERROR(INDEX(#REF!,MATCH(C6,#REF!,0)),"") | E6: =IFERROR(INDEX(#REF!,MATCH(C6,#REF!,0)),"") | F6: =IFERROR(INDEX(#REF!,MATCH(C6,#REF!,0)),"") | G6: =IFERROR(INDEX(#REF!,MATCH(C6,#REF!,0)),"") | H6: =IFERROR(INDEX(#REF!,MATCH(C6,#REF!,0)),"") | I6: =IFERROR(INDEX(#REF!,MATCH(C6,#REF!,0)),"") | J6: =IFERROR(INDEX(#REF!,MATCH(C6,#REF!,0)),"") | K6: =IFERROR(INDEX(#REF!,MATCH(C6,#REF!,0)),"") | P6: =IFERROR(INDEX(#REF!,MATCH(O6,#REF!,0)),"") | Q6: =IFERROR(INDEX(#REF!,MATCH(O6,#REF!,0)),"") | R6: =O6 -> 0 | X6: =IF(W6<>"",W6-B6,IF(B6<>"",TODAY()-B6,"")) | AA6: =IF(O6="","",IF(W6<>"",IF(OR(U6="Perdu",U6="Vole",U6="Reforme",U6="En maintenance",U6="En reparation"),U6,"Disponible"),IF(AND(V6<>"",TODAY()>V6),"En retard","Affecte"))) | AB6: =IF(AND(O6<>"",W6="",V6<>"",TODAY()>V6),"OUI","NON") -> NON | AC6: =IF(O6<>"",O6&"|"&TEXT(B6,"YYYYMMDD"),"") | AD6: =IF(O6<>"",COUNTIFS($O$5:O6,O6),"") | AE6: =IF(O6<>"",O6&"|R"&AD6,"") | AF6: =IF(AB6="OUI",COUNTIFS($AB$5:AB6,"OUI"),"") | AG6: =IF(AB6="OUI","RETARD|R"&AF6,"") | AH6: =IF(AND(O6<>"",W6=""),IF(COUNTIFS($O$5:$O$84,O6,$W$5:$W$84,"")>1,"OUI","NON"),"NON") -> NON
A7: ="MVT-"&TEXT(ROW()-4,"0000") -> MVT-0003 | D7: =IFERROR(INDEX(#REF!,MATCH(C7,#REF!,0)),"") | E7: =IFERROR(INDEX(#REF!,MATCH(C7,#REF!,0)),"") | F7: =IFERROR(INDEX(#REF!,MATCH(C7,#REF!,0)),"") | G7: =IFERROR(INDEX(#REF!,MATCH(C7,#REF!,0)),"") | H7: =IFERROR(INDEX(#REF!,MATCH(C7,#REF!,0)),"") | I7: =IFERROR(INDEX(#REF!,MATCH(C7,#REF!,0)),"") | J7: =IFERROR(INDEX(#REF!,MATCH(C7,#REF!,0)),"") | K7: =IFERROR(INDEX(#REF!,MATCH(C7,#REF!,0)),"") | P7: =IFERROR(INDEX(#REF!,MATCH(O7,#REF!,0)),"") | Q7: =IFERROR(INDEX(#REF!,MATCH(O7,#REF!,0)),"") | R7: =O7 -> 0 | X7: =IF(W7<>"",W7-B7,IF(B7<>"",TODAY()-B7,"")) | AA7: =IF(O7="","",IF(W7<>"",IF(OR(U7="Perdu",U7="Vole",U7="Reforme",U7="En maintenance",U7="En reparation"),U7,"Disponible"),IF(AND(V7<>"",TODAY()>V7),"En retard","Affecte"))) | AB7: =IF(AND(O7<>"",W7="",V7<>"",TODAY()>V7),"OUI","NON") -> NON | AC7: =IF(O7<>"",O7&"|"&TEXT(B7,"YYYYMMDD"),"") | AD7: =IF(O7<>"",COUNTIFS($O$5:O7,O7),"") | AE7: =IF(O7<>"",O7&"|R"&AD7,"") | AF7: =IF(AB7="OUI",COUNTIFS($AB$5:AB7,"OUI"),"") | AG7: =IF(AB7="OUI","RETARD|R"&AF7,"") | AH7: =IF(AND(O7<>"",W7=""),IF(COUNTIFS($O$5:$O$84,O7,$W$5:$W$84,"")>1,"OUI","NON"),"NON") -> NON
A8: ="MVT-"&TEXT(ROW()-4,"0000") -> MVT-0004 | D8: =IFERROR(INDEX(#REF!,MATCH(C8,#REF!,0)),"") | E8: =IFERROR(INDEX(#REF!,MATCH(C8,#REF!,0)),"") | F8: =IFERROR(INDEX(#REF!,MATCH(C8,#REF!,0)),"") | G8: =IFERROR(INDEX(#REF!,MATCH(C8,#REF!,0)),"") | H8: =IFERROR(INDEX(#REF!,MATCH(C8,#REF!,0)),"") | I8: =IFERROR(INDEX(#REF!,MATCH(C8,#REF!,0)),"") | J8: =IFERROR(INDEX(#REF!,MATCH(C8,#REF!,0)),"") | K8: =IFERROR(INDEX(#REF!,MATCH(C8,#REF!,0)),"") | P8: =IFERROR(INDEX(#REF!,MATCH(O8,#REF!,0)),"") | Q8: =IFERROR(INDEX(#REF!,MATCH(O8,#REF!,0)),"") | R8: =O8 -> 0 | X8: =IF(W8<>"",W8-B8,IF(B8<>"",TODAY()-B8,"")) | AA8: =IF(O8="","",IF(W8<>"",IF(OR(U8="Perdu",U8="Vole",U8="Reforme",U8="En maintenance",U8="En reparation"),U8,"Disponible"),IF(AND(V8<>"",TODAY()>V8),"En retard","Affecte"))) | AB8: =IF(AND(O8<>"",W8="",V8<>"",TODAY()>V8),"OUI","NON") -> NON | AC8: =IF(O8<>"",O8&"|"&TEXT(B8,"YYYYMMDD"),"") | AD8: =IF(O8<>"",COUNTIFS($O$5:O8,O8),"") | AE8: =IF(O8<>"",O8&"|R"&AD8,"") | AF8: =IF(AB8="OUI",COUNTIFS($AB$5:AB8,"OUI"),"") | AG8: =IF(AB8="OUI","RETARD|R"&AF8,"") | AH8: =IF(AND(O8<>"",W8=""),IF(COUNTIFS($O$5:$O$84,O8,$W$5:$W$84,"")>1,"OUI","NON"),"NON") -> NON
A9: ="MVT-"&TEXT(ROW()-4,"0000") -> MVT-0005 | D9: =IFERROR(INDEX(#REF!,MATCH(C9,#REF!,0)),"") | E9: =IFERROR(INDEX(#REF!,MATCH(C9,#REF!,0)),"") | F9: =IFERROR(INDEX(#REF!,MATCH(C9,#REF!,0)),"") | G9: =IFERROR(INDEX(#REF!,MATCH(C9,#REF!,0)),"") | H9: =IFERROR(INDEX(#REF!,MATCH(C9,#REF!,0)),"") | I9: =IFERROR(INDEX(#REF!,MATCH(C9,#REF!,0)),"") | J9: =IFERROR(INDEX(#REF!,MATCH(C9,#REF!,0)),"") | K9: =IFERROR(INDEX(#REF!,MATCH(C9,#REF!,0)),"") | P9: =IFERROR(INDEX(#REF!,MATCH(O9,#REF!,0)),"") | Q9: =IFERROR(INDEX(#REF!,MATCH(O9,#REF!,0)),"") | R9: =O9 -> 0 | X9: =IF(W9<>"",W9-B9,IF(B9<>"",TODAY()-B9,"")) | AA9: =IF(O9="","",IF(W9<>"",IF(OR(U9="Perdu",U9="Vole",U9="Reforme",U9="En maintenance",U9="En reparation"),U9,"Disponible"),IF(AND(V9<>"",TODAY()>V9),"En retard","Affecte"))) | AB9: =IF(AND(O9<>"",W9="",V9<>"",TODAY()>V9),"OUI","NON") -> NON | AC9: =IF(O9<>"",O9&"|"&TEXT(B9,"YYYYMMDD"),"") | AD9: =IF(O9<>"",COUNTIFS($O$5:O9,O9),"") | AE9: =IF(O9<>"",O9&"|R"&AD9,"") | AF9: =IF(AB9="OUI",COUNTIFS($AB$5:AB9,"OUI"),"") | AG9: =IF(AB9="OUI","RETARD|R"&AF9,"") | AH9: =IF(AND(O9<>"",W9=""),IF(COUNTIFS($O$5:$O$84,O9,$W$5:$W$84,"")>1,"OUI","NON"),"NON") -> NON
A10: ="MVT-"&TEXT(ROW()-4,"0000") -> MVT-0006 | D10: =IFERROR(INDEX(#REF!,MATCH(C10,#REF!,0)),"") | E10: =IFERROR(INDEX(#REF!,MATCH(C10,#REF!,0)),"") | F10: =IFERROR(INDEX(#REF!,MATCH(C10,#REF!,0)),"") | G10: =IFERROR(INDEX(#REF!,MATCH(C10,#REF!,0)),"") | H10: =IFERROR(INDEX(#REF!,MATCH(C10,#REF!,0)),"") | I10: =IFERROR(INDEX(#REF!,MATCH(C10,#REF!,0)),"") | J10: =IFERROR(INDEX(#REF!,MATCH(C10,#REF!,0)),"") | K10: =IFERROR(INDEX(#REF!,MATCH(C10,#REF!,0)),"") | P10: =IFERROR(INDEX(#REF!,MATCH(O10,#REF!,0)),"") | Q10: =IFERROR(INDEX(#REF!,MATCH(O10,#REF!,0)),"") | R10: =O10 -> 0 | X10: =IF(W10<>"",W10-B10,IF(B10<>"",TODAY()-B10,"")) | AA10: =IF(O10="","",IF(W10<>"",IF(OR(U10="Perdu",U10="Vole",U10="Reforme",U10="En maintenance",U10="En reparation"),U10,"Disponible"),IF(AND(V10<>"",TODAY()>V10),"En retard","Affecte"))) | AB10: =IF(AND(O10<>"",W10="",V10<>"",TODAY()>V10),"OUI","NON") -> NON | AC10: =IF(O10<>"",O10&"|"&TEXT(B10,"YYYYMMDD"),"") | AD10: =IF(O10<>"",COUNTIFS($O$5:O10,O10),"") | AE10: =IF(O10<>"",O10&"|R"&AD10,"") | AF10: =IF(AB10="OUI",COUNTIFS($AB$5:AB10,"OUI"),"") | AG10: =IF(AB10="OUI","RETARD|R"&AF10,"") | AH10: =IF(AND(O10<>"",W10=""),IF(COUNTIFS($O$5:$O$84,O10,$W$5:$W$84,"")>1,"OUI","NON"),"NON") -> NON
A11: ="MVT-"&TEXT(ROW()-4,"0000") -> MVT-0007 | D11: =IFERROR(INDEX(#REF!,MATCH(C11,#REF!,0)),"") | E11: =IFERROR(INDEX(#REF!,MATCH(C11,#REF!,0)),"") | F11: =IFERROR(INDEX(#REF!,MATCH(C11,#REF!,0)),"") | G11: =IFERROR(INDEX(#REF!,MATCH(C11,#REF!,0)),"") | H11: =IFERROR(INDEX(#REF!,MATCH(C11,#REF!,0)),"") | I11: =IFERROR(INDEX(#REF!,MATCH(C11,#REF!,0)),"") | J11: =IFERROR(INDEX(#REF!,MATCH(C11,#REF!,0)),"") | K11: =IFERROR(INDEX(#REF!,MATCH(C11,#REF!,0)),"") | P11: =IFERROR(INDEX(#REF!,MATCH(O11,#REF!,0)),"") | Q11: =IFERROR(INDEX(#REF!,MATCH(O11,#REF!,0)),"") | R11: =O11 -> 0 | X11: =IF(W11<>"",W11-B11,IF(B11<>"",TODAY()-B11,"")) | AA11: =IF(O11="","",IF(W11<>"",IF(OR(U11="Perdu",U11="Vole",U11="Reforme",U11="En maintenance",U11="En reparation"),U11,"Disponible"),IF(AND(V11<>"",TODAY()>V11),"En retard","Affecte"))) | AB11: =IF(AND(O11<>"",W11="",V11<>"",TODAY()>V11),"OUI","NON") -> NON | AC11: =IF(O11<>"",O11&"|"&TEXT(B11,"YYYYMMDD"),"") | AD11: =IF(O11<>"",COUNTIFS($O$5:O11,O11),"") | AE11: =IF(O11<>"",O11&"|R"&AD11,"") | AF11: =IF(AB11="OUI",COUNTIFS($AB$5:AB11,"OUI"),"") | AG11: =IF(AB11="OUI","RETARD|R"&AF11,"") | AH11: =IF(AND(O11<>"",W11=""),IF(COUNTIFS($O$5:$O$84,O11,$W$5:$W$84,"")>1,"OUI","NON"),"NON") -> NON
A12: ="MVT-"&TEXT(ROW()-4,"0000") -> MVT-0008 | D12: =IFERROR(INDEX(#REF!,MATCH(C12,#REF!,0)),"") | E12: =IFERROR(INDEX(#REF!,MATCH(C12,#REF!,0)),"") | F12: =IFERROR(INDEX(#REF!,MATCH(C12,#REF!,0)),"") | G12: =IFERROR(INDEX(#REF!,MATCH(C12,#REF!,0)),"") | H12: =IFERROR(INDEX(#REF!,MATCH(C12,#REF!,0)),"") | I12: =IFERROR(INDEX(#REF!,MATCH(C12,#REF!,0)),"") | J12: =IFERROR(INDEX(#REF!,MATCH(C12,#REF!,0)),"") | K12: =IFERROR(INDEX(#REF!,MATCH(C12,#REF!,0)),"") | P12: =IFERROR(INDEX(#REF!,MATCH(O12,#REF!,0)),"") | Q12: =IFERROR(INDEX(#REF!,MATCH(O12,#REF!,0)),"") | R12: =O12 -> 0 | X12: =IF(W12<>"",W12-B12,IF(B12<>"",TODAY()-B12,"")) | AA12: =IF(O12="","",IF(W12<>"",IF(OR(U12="Perdu",U12="Vole",U12="Reforme",U12="En maintenance",U12="En reparation"),U12,"Disponible"),IF(AND(V12<>"",TODAY()>V12),"En retard","Affecte"))) | AB12: =IF(AND(O12<>"",W12="",V12<>"",TODAY()>V12),"OUI","NON") -> NON | AC12: =IF(O12<>"",O12&"|"&TEXT(B12,"YYYYMMDD"),"") | AD12: =IF(O12<>"",COUNTIFS($O$5:O12,O12),"") | AE12: =IF(O12<>"",O12&"|R"&AD12,"") | AF12: =IF(AB12="OUI",COUNTIFS($AB$5:AB12,"OUI"),"") | AG12: =IF(AB12="OUI","RETARD|R"&AF12,"") | AH12: =IF(AND(O12<>"",W12=""),IF(COUNTIFS($O$5:$O$84,O12,$W$5:$W$84,"")>1,"OUI","NON"),"NON") -> NON
A13: ="MVT-"&TEXT(ROW()-4,"0000") -> MVT-0009 | D13: =IFERROR(INDEX(#REF!,MATCH(C13,#REF!,0)),"") | E13: =IFERROR(INDEX(#REF!,MATCH(C13,#REF!,0)),"") | F13: =IFERROR(INDEX(#REF!,MATCH(C13,#REF!,0)),"") | G13: =IFERROR(INDEX(#REF!,MATCH(C13,#REF!,0)),"") | H13: =IFERROR(INDEX(#REF!,MATCH(C13,#REF!,0)),"") | I13: =IFERROR(INDEX(#REF!,MATCH(C13,#REF!,0)),"") | J13: =IFERROR(INDEX(#REF!,MATCH(C13,#REF!,0)),"") | K13: =IFERROR(INDEX(#REF!,MATCH(C13,#REF!,0)),"") | P13: =IFERROR(INDEX(#REF!,MATCH(O13,#REF!,0)),"") | Q13: =IFERROR(INDEX(#REF!,MATCH(O13,#REF!,0)),"") | R13: =O13 -> 0 | X13: =IF(W13<>"",W13-B13,IF(B13<>"",TODAY()-B13,"")) | AA13: =IF(O13="","",IF(W13<>"",IF(OR(U13="Perdu",U13="Vole",U13="Reforme",U13="En maintenance",U13="En reparation"),U13,"Disponible"),IF(AND(V13<>"",TODAY()>V13),"En retard","Affecte"))) | AB13: =IF(AND(O13<>"",W13="",V13<>"",TODAY()>V13),"OUI","NON") -> NON | AC13: =IF(O13<>"",O13&"|"&TEXT(B13,"YYYYMMDD"),"") | AD13: =IF(O13<>"",COUNTIFS($O$5:O13,O13),"") | AE13: =IF(O13<>"",O13&"|R"&AD13,"") | AF13: =IF(AB13="OUI",COUNTIFS($AB$5:AB13,"OUI"),"") | AG13: =IF(AB13="OUI","RETARD|R"&AF13,"") | AH13: =IF(AND(O13<>"",W13=""),IF(COUNTIFS($O$5:$O$84,O13,$W$5:$W$84,"")>1,"OUI","NON"),"NON") -> NON
A14: ="MVT-"&TEXT(ROW()-4,"0000") -> MVT-0010 | D14: =IFERROR(INDEX(#REF!,MATCH(C14,#REF!,0)),"") | E14: =IFERROR(INDEX(#REF!,MATCH(C14,#REF!,0)),"") | F14: =IFERROR(INDEX(#REF!,MATCH(C14,#REF!,0)),"") | G14: =IFERROR(INDEX(#REF!,MATCH(C14,#REF!,0)),"") | H14: =IFERROR(INDEX(#REF!,MATCH(C14,#REF!,0)),"") | I14: =IFERROR(INDEX(#REF!,MATCH(C14,#REF!,0)),"") | J14: =IFERROR(INDEX(#REF!,MATCH(C14,#REF!,0)),"") | K14: =IFERROR(INDEX(#REF!,MATCH(C14,#REF!,0)),"") | P14: =IFERROR(INDEX(#REF!,MATCH(O14,#REF!,0)),"") | Q14: =IFERROR(INDEX(#REF!,MATCH(O14,#REF!,0)),"") | R14: =O14 -> 0 | X14: =IF(W14<>"",W14-B14,IF(B14<>"",TODAY()-B14,"")) | AA14: =IF(O14="","",IF(W14<>"",IF(OR(U14="Perdu",U14="Vole",U14="Reforme",U14="En maintenance",U14="En reparation"),U14,"Disponible"),IF(AND(V14<>"",TODAY()>V14),"En retard","Affecte"))) | AB14: =IF(AND(O14<>"",W14="",V14<>"",TODAY()>V14),"OUI","NON") -> NON | AC14: =IF(O14<>"",O14&"|"&TEXT(B14,"YYYYMMDD"),"") | AD14: =IF(O14<>"",COUNTIFS($O$5:O14,O14),"") | AE14: =IF(O14<>"",O14&"|R"&AD14,"") | AF14: =IF(AB14="OUI",COUNTIFS($AB$5:AB14,"OUI"),"") | AG14: =IF(AB14="OUI","RETARD|R"&AF14,"") | AH14: =IF(AND(O14<>"",W14=""),IF(COUNTIFS($O$5:$O$84,O14,$W$5:$W$84,"")>1,"OUI","NON"),"NON") -> NON
A15: ="MVT-"&TEXT(ROW()-4,"0000") -> MVT-0011 | D15: =IFERROR(INDEX(#REF!,MATCH(C15,#REF!,0)),"") | E15: =IFERROR(INDEX(#REF!,MATCH(C15,#REF!,0)),"") | F15: =IFERROR(INDEX(#REF!,MATCH(C15,#REF!,0)),"") | G15: =IFERROR(INDEX(#REF!,MATCH(C15,#REF!,0)),"") | H15: =IFERROR(INDEX(#REF!,MATCH(C15,#REF!,0)),"") | I15: =IFERROR(INDEX(#REF!,MATCH(C15,#REF!,0)),"") | J15: =IFERROR(INDEX(#REF!,MATCH(C15,#REF!,0)),"") | K15: =IFERROR(INDEX(#REF!,MATCH(C15,#REF!,0)),"") | P15: =IFERROR(INDEX(#REF!,MATCH(O15,#REF!,0)),"") | Q15: =IFERROR(INDEX(#REF!,MATCH(O15,#REF!,0)),"") | R15: =O15 -> 0 | X15: =IF(W15<>"",W15-B15,IF(B15<>"",TODAY()-B15,"")) | AA15: =IF(O15="","",IF(W15<>"",IF(OR(U15="Perdu",U15="Vole",U15="Reforme",U15="En maintenance",U15="En reparation"),U15,"Disponible"),IF(AND(V15<>"",TODAY()>V15),"En retard","Affecte"))) | AB15: =IF(AND(O15<>"",W15="",V15<>"",TODAY()>V15),"OUI","NON") -> NON | AC15: =IF(O15<>"",O15&"|"&TEXT(B15,"YYYYMMDD"),"") | AD15: =IF(O15<>"",COUNTIFS($O$5:O15,O15),"") | AE15: =IF(O15<>"",O15&"|R"&AD15,"") | AF15: =IF(AB15="OUI",COUNTIFS($AB$5:AB15,"OUI"),"") | AG15: =IF(AB15="OUI","RETARD|R"&AF15,"") | AH15: =IF(AND(O15<>"",W15=""),IF(COUNTIFS($O$5:$O$84,O15,$W$5:$W$84,"")>1,"OUI","NON"),"NON") -> NON
A16: ="MVT-"&TEXT(ROW()-4,"0000") -> MVT-0012 | D16: =IFERROR(INDEX(#REF!,MATCH(C16,#REF!,0)),"") | E16: =IFERROR(INDEX(#REF!,MATCH(C16,#REF!,0)),"") | F16: =IFERROR(INDEX(#REF!,MATCH(C16,#REF!,0)),"") | G16: =IFERROR(INDEX(#REF!,MATCH(C16,#REF!,0)),"") | H16: =IFERROR(INDEX(#REF!,MATCH(C16,#REF!,0)),"") | I16: =IFERROR(INDEX(#REF!,MATCH(C16,#REF!,0)),"") | J16: =IFERROR(INDEX(#REF!,MATCH(C16,#REF!,0)),"") | K16: =IFERROR(INDEX(#REF!,MATCH(C16,#REF!,0)),"") | P16: =IFERROR(INDEX(#REF!,MATCH(O16,#REF!,0)),"") | Q16: =IFERROR(INDEX(#REF!,MATCH(O16,#REF!,0)),"") | R16: =O16 -> 0 | X16: =IF(W16<>"",W16-B16,IF(B16<>"",TODAY()-B16,"")) | AA16: =IF(O16="","",IF(W16<>"",IF(OR(U16="Perdu",U16="Vole",U16="Reforme",U16="En maintenance",U16="En reparation"),U16,"Disponible"),IF(AND(V16<>"",TODAY()>V16),"En retard","Affecte"))) | AB16: =IF(AND(O16<>"",W16="",V16<>"",TODAY()>V16),"OUI","NON") -> NON | AC16: =IF(O16<>"",O16&"|"&TEXT(B16,"YYYYMMDD"),"") | AD16: =IF(O16<>"",COUNTIFS($O$5:O16,O16),"") | AE16: =IF(O16<>"",O16&"|R"&AD16,"") | AF16: =IF(AB16="OUI",COUNTIFS($AB$5:AB16,"OUI"),"") | AG16: =IF(AB16="OUI","RETARD|R"&AF16,"") | AH16: =IF(AND(O16<>"",W16=""),IF(COUNTIFS($O$5:$O$84,O16,$W$5:$W$84,"")>1,"OUI","NON"),"NON") -> NON
A17: ="MVT-"&TEXT(ROW()-4,"0000") -> MVT-0013 | D17: =IFERROR(INDEX(#REF!,MATCH(C17,#REF!,0)),"") | E17: =IFERROR(INDEX(#REF!,MATCH(C17,#REF!,0)),"") | F17: =IFERROR(INDEX(#REF!,MATCH(C17,#REF!,0)),"") | G17: =IFERROR(INDEX(#REF!,MATCH(C17,#REF!,0)),"") | H17: =IFERROR(INDEX(#REF!,MATCH(C17,#REF!,0)),"") | I17: =IFERROR(INDEX(#REF!,MATCH(C17,#REF!,0)),"") | J17: =IFERROR(INDEX(#REF!,MATCH(C17,#REF!,0)),"") | K17: =IFERROR(INDEX(#REF!,MATCH(C17,#REF!,0)),"") | P17: =IFERROR(INDEX(#REF!,MATCH(O17,#REF!,0)),"") | Q17: =IFERROR(INDEX(#REF!,MATCH(O17,#REF!,0)),"") | R17: =O17 -> 0 | X17: =IF(W17<>"",W17-B17,IF(B17<>"",TODAY()-B17,"")) | AA17: =IF(O17="","",IF(W17<>"",IF(OR(U17="Perdu",U17="Vole",U17="Reforme",U17="En maintenance",U17="En reparation"),U17,"Disponible"),IF(AND(V17<>"",TODAY()>V17),"En retard","Affecte"))) | AB17: =IF(AND(O17<>"",W17="",V17<>"",TODAY()>V17),"OUI","NON") -> NON | AC17: =IF(O17<>"",O17&"|"&TEXT(B17,"YYYYMMDD"),"") | AD17: =IF(O17<>"",COUNTIFS($O$5:O17,O17),"") | AE17: =IF(O17<>"",O17&"|R"&AD17,"") | AF17: =IF(AB17="OUI",COUNTIFS($AB$5:AB17,"OUI"),"") | AG17: =IF(AB17="OUI","RETARD|R"&AF17,"") | AH17: =IF(AND(O17<>"",W17=""),IF(COUNTIFS($O$5:$O$84,O17,$W$5:$W$84,"")>1,"OUI","NON"),"NON") -> NON
... A84: ="MVT-"&TEXT(ROW()-4,"0000") -> MVT-0080 | D84: =IFERROR(INDEX(#REF!,MATCH(C84,#REF!,0)),"") | E84: =IFERROR(INDEX(#REF!,MATCH(C84,#REF!,0)),"") | F84: =IFERROR(INDEX(#REF!,MATCH(C84,#REF!,0)),"") | G84: =IFERROR(INDEX(#REF!,MATCH(C84,#REF!,0)),"") | H84: =IFERROR(INDEX(#REF!,MATCH(C84,#REF!,0)),"") | I84: =IFERROR(INDEX(#REF!,MATCH(C84,#REF!,0)),"") | J84: =IFERROR(INDEX(#REF!,MATCH(C84,#REF!,0)),"") | K84: =IFERROR(INDEX(#REF!,MATCH(C84,#REF!,0)),"") | P84: =IFERROR(INDEX(#REF!,MATCH(O84,#REF!,0)),"") | Q84: =IFERROR(INDEX(#REF!,MATCH(O84,#REF!,0)),"") | R84: =O84 -> 0 | X84: =IF(W84<>"",W84-B84,IF(B84<>"",TODAY()-B84,"")) | AA84: =IF(O84="","",IF(W84<>"",IF(OR(U84="Perdu",U84="Vole",U84="Reforme",U84="En maintenance",U84="En reparation"),U84,"Disponible"),IF(AND(V84<>"",TODAY()>V84),"En retard","Affecte"))) | AB84: =IF(AND(O84<>"",W84="",V84<>"",TODAY()>V84),"OUI","NON") -> NON | AC84: =IF(O84<>"",O84&"|"&TEXT(B84,"YYYYMMDD"),"") | AD84: =IF(O84<>"",COUNTIFS($O$5:O84,O84),"") | AE84: =IF(O84<>"",O84&"|R"&AD84,"") | AF84: =IF(AB84="OUI",COUNTIFS($AB$5:AB84,"OUI"),"") | AG84: =IF(AB84="OUI","RETARD|R"&AF84,"") | AH84: =IF(AND(O84<>"",W84=""),IF(COUNTIFS($O$5:$O$84,O84,$W$5:$W$84,"")>1,"OUI","NON"),"NON") -> NON

Sheet Recherche_Materiel
A1: RECHERCHE INSTANTANEE - FICHE MATERIEL
A2: Saisissez un Code Materiel (ex: EQ-001) dans la case bleue ci-dessous : la fiche se met a jour automatiquement avec sa position actuelle, son statut et son historique de mouvements.
A4: Code Materiel a rechercher : | B4: EQ-001
A6: Designation | B6: =IFERROR(INDEX(#REF!,MATCH(B4,#REF!,0)),"Non trouve") -> Non trouve
A7: Marque | B7: =IFERROR(IF(INDEX(#REF!,MATCH(B4,#REF!,0))="","",INDEX(#REF!,MATCH(B4,#REF!,0))),"")
A8: Numero de serie | B8: =IFERROR(IF(INDEX(#REF!,MATCH(B4,#REF!,0))="","",INDEX(#REF!,MATCH(B4,#REF!,0))),"")
A9: Etat (fiche equipement) | B9: =IFERROR(INDEX(#REF!,MATCH(B4,#REF!,0)),"")
A10: Localisation declaree | B10: =IFERROR(INDEX(#REF!,MATCH(B4,#REF!,0)),"")
A11: Projet actuel | B11: =IFERROR(INDEX(#REF!,MATCH(B4,#REF!,0)),"")
A12: Statut actuel (tracabilite) | B12: =IFERROR(INDEX(#REF!,MATCH(B4,#REF!,0)),"")
A13: Dernier mouvement | B13: =IFERROR(INDEX(#REF!,MATCH(B4,#REF!,0)),"")
A14: Jours depuis dernier mouvement | B14: =IFERROR(INDEX(#REF!,MATCH(B4,#REF!,0)),"")
A15: Nombre total de mouvements (historique) | B15: =COUNTIF(#REF!,B4) -> #REF!
A17: HISTORIQUE COMPLET DES MOUVEMENTS DE CE MATERIEL
A18: N Mouvement | B18: Date Sortie | C18: Projet | D18: Etat avant sortie | E18: Date retour prevue | F18: Date reelle retour
A19: =IFERROR(INDEX(#REF!,MATCH(B4&"|R"&1,#REF!,0)),"") | B19: =IFERROR(INDEX(#REF!,MATCH(B4&"|R"&1,#REF!,0)),"") | C19: =IFERROR(INDEX(#REF!,MATCH(B4&"|R"&1,#REF!,0)),"") | D19: =IFERROR(INDEX(#REF!,MATCH(B4&"|R"&1,#REF!,0)),"") | E19: =IFERROR(INDEX(#REF!,MATCH(B4&"|R"&1,#REF!,0)),"") | F19: =IFERROR(INDEX(#REF!,MATCH(B4&"|R"&1,#REF!,0)),"")
A20: =IFERROR(INDEX(#REF!,MATCH(B4&"|R"&2,#REF!,0)),"") | B20: =IFERROR(INDEX(#REF!,MATCH(B4&"|R"&2,#REF!,0)),"") | C20: =IFERROR(INDEX(#REF!,MATCH(B4&"|R"&2,#REF!,0)),"") | D20: =IFERROR(INDEX(#REF!,MATCH(B4&"|R"&2,#REF!,0)),"") | E20: =IFERROR(INDEX(#REF!,MATCH(B4&"|R"&2,#REF!,0)),"") | F20: =IFERROR(INDEX(#REF!,MATCH(B4&"|R"&2,#REF!,0)),"")
A21: =IFERROR(INDEX(#REF!,MATCH(B4&"|R"&3,#REF!,0)),"") | B21: =IFERROR(INDEX(#REF!,MATCH(B4&"|R"&3,#REF!,0)),"") | C21: =IFERROR(INDEX(#REF!,MATCH(B4&"|R"&3,#REF!,0)),"") | D21: =IFERROR(INDEX(#REF!,MATCH(B4&"|R"&3,#REF!,0)),"") | E21: =IFERROR(INDEX(#REF!,MATCH(B4&"|R"&3,#REF!,0)),"") | F21: =IFERROR(INDEX(#REF!,MATCH(B4&"|R"&3,#REF!,0)),"")
A22: =IFERROR(INDEX(#REF!,MATCH(B4&"|R"&4,#REF!,0)),"") | B22: =IFERROR(INDEX(#REF!,MATCH(B4&"|R"&4,#REF!,0)),"") | C22: =IFERROR(INDEX(#REF!,MATCH(B4&"|R"&4,#REF!,0)),"") | D22: =IFERROR(INDEX(#REF!,MATCH(B4&"|R"&4,#REF!,0)),"") | E22: =IFERROR(INDEX(#REF!,MATCH(B4&"|R"&4,#REF!,0)),"") | F22: =IFERROR(INDEX(#REF!,MATCH(B4&"|R"&4,#REF!,0)),"")
A23: =IFERROR(INDEX(#REF!,MATCH(B4&"|R"&5,#REF!,0)),"") | B23: =IFERROR(INDEX(#REF!,MATCH(B4&"|R"&5,#REF!,0)),"") | C23: =IFERROR(INDEX(#REF!,MATCH(B4&"|R"&5,#REF!,0)),"") | D23: =IFERROR(INDEX(#REF!,MATCH(B4&"|R"&5,#REF!,0)),"") | E23: =IFERROR(INDEX(#REF!,MATCH(B4&"|R"&5,#REF!,0)),"") | F23: =IFERROR(INDEX(#REF!,MATCH(B4&"|R"&5,#REF!,0)),"")
A24: =IFERROR(INDEX(#REF!,MATCH(B4&"|R"&6,#REF!,0)),"") | B24: =IFERROR(INDEX(#REF!,MATCH(B4&"|R"&6,#REF!,0)),"") | C24: =IFERROR(INDEX(#REF!,MATCH(B4&"|R"&6,#REF!,0)),"") | D24: =IFERROR(INDEX(#REF!,MATCH(B4&"|R"&6,#REF!,0)),"") | E24: =IFERROR(INDEX(#REF!,MATCH(B4&"|R"&6,#REF!,0)),"") | F24: =IFERROR(INDEX(#REF!,MATCH(B4&"|R"&6,#REF!,0)),"")
A25: =IFERROR(INDEX(#REF!,MATCH(B4&"|R"&7,#REF!,0)),"") | B25: =IFERROR(INDEX(#REF!,MATCH(B4&"|R"&7,#REF!,0)),"") | C25: =IFERROR(INDEX(#REF!,MATCH(B4&"|R"&7,#REF!,0)),"") | D25: =IFERROR(INDEX(#REF!,MATCH(B4&"|R"&7,#REF!,0)),"") | E25: =IFERROR(INDEX(#REF!,MATCH(B4&"|R"&7,#REF!,0)),"") | F25: =IFERROR(INDEX(#REF!,MATCH(B4&"|R"&7,#REF!,0)),"")
A26: =IFERROR(INDEX(#REF!,MATCH(B4&"|R"&8,#REF!,0)),"") | B26: =IFERROR(INDEX(#REF!,MATCH(B4&"|R"&8,#REF!,0)),"") | C26: =IFERROR(INDEX(#REF!,MATCH(B4&"|R"&8,#REF!,0)),"") | D26: =IFERROR(INDEX(#REF!,MATCH(B4&"|R"&8,#REF!,0)),"") | E26: =IFERROR(INDEX(#REF!,MATCH(B4&"|R"&8,#REF!,0)),"") | F26: =IFERROR(INDEX(#REF!,MATCH(B4&"|R"&8,#REF!,0)),"")
A27: =IFERROR(INDEX(#REF!,MATCH(B4&"|R"&9,#REF!,0)),"") | B27: =IFERROR(INDEX(#REF!,MATCH(B4&"|R"&9,#REF!,0)),"") | C27: =IFERROR(INDEX(#REF!,MATCH(B4&"|R"&9,#REF!,0)),"") | D27: =IFERROR(INDEX(#REF!,MATCH(B4&"|R"&9,#REF!,0)),"") | E27: =IFERROR(INDEX(#REF!,MATCH(B4&"|R"&9,#REF!,0)),"") | F27: =IFERROR(INDEX(#REF!,MATCH(B4&"|R"&9,#REF!,0)),"")
A28: =IFERROR(INDEX(#REF!,MATCH(B4&"|R"&10,#REF!,0)),"") | B28: =IFERROR(INDEX(#REF!,MATCH(B4&"|R"&10,#REF!,0)),"") | C28: =IFERROR(INDEX(#REF!,MATCH(B4&"|R"&10,#REF!,0)),"") | D28: =IFERROR(INDEX(#REF!,MATCH(B4&"|R"&10,#REF!,0)),"") | E28: =IFERROR(INDEX(#REF!,MATCH(B4&"|R"&10,#REF!,0)),"") | F28: =IFERROR(INDEX(#REF!,MATCH(B4&"|R"&10,#REF!,0)),"")
A29: =IFERROR(INDEX(#REF!,MATCH(B4&"|R"&11,#REF!,0)),"") | B29: =IFERROR(INDEX(#REF!,MATCH(B4&"|R"&11,#REF!,0)),"") | C29: =IFERROR(INDEX(#REF!,MATCH(B4&"|R"&11,#REF!,0)),"") | D29: =IFERROR(INDEX(#REF!,MATCH(B4&"|R"&11,#REF!,0)),"") | E29: =IFERROR(INDEX(#REF!,MATCH(B4&"|R"&11,#REF!,0)),"") | F29: =IFERROR(INDEX(#REF!,MATCH(B4&"|R"&11,#REF!,0)),"")
A30: =IFERROR(INDEX(#REF!,MATCH(B4&"|R"&12,#REF!,0)),"") | B30: =IFERROR(INDEX(#REF!,MATCH(B4&"|R"&12,#REF!,0)),"") | C30: =IFERROR(INDEX(#REF!,MATCH(B4&"|R"&12,#REF!,0)),"") | D30: =IFERROR(INDEX(#REF!,MATCH(B4&"|R"&12,#REF!,0)),"") | E30: =IFERROR(INDEX(#REF!,MATCH(B4&"|R"&12,#REF!,0)),"") | F30: =IFERROR(INDEX(#REF!,MATCH(B4&"|R"&12,#REF!,0)),"")
A31: =IFERROR(INDEX(#REF!,MATCH(B4&"|R"&13,#REF!,0)),"") | B31: =IFERROR(INDEX(#REF!,MATCH(B4&"|R"&13,#REF!,0)),"") | C31: =IFERROR(INDEX(#REF!,MATCH(B4&"|R"&13,#REF!,0)),"") | D31: =IFERROR(INDEX(#REF!,MATCH(B4&"|R"&13,#REF!,0)),"") | E31: =IFERROR(INDEX(#REF!,MATCH(B4&"|R"&13,#REF!,0)),"") | F31: =IFERROR(INDEX(#REF!,MATCH(B4&"|R"&13,#REF!,0)),"")
A32: =IFERROR(INDEX(#REF!,MATCH(B4&"|R"&14,#REF!,0)),"") | B32: =IFERROR(INDEX(#REF!,MATCH(B4&"|R"&14,#REF!,0)),"") | C32: =IFERROR(INDEX(#REF!,MATCH(B4&"|R"&14,#REF!,0)),"") | D32: =IFERROR(INDEX(#REF!,MATCH(B4&"|R"&14,#REF!,0)),"") | E32: =IFERROR(INDEX(#REF!,MATCH(B4&"|R"&14,#REF!,0)),"") | F32: =IFERROR(INDEX(#REF!,MATCH(B4&"|R"&14,#REF!,0)),"")
A33: =IFERROR(INDEX(#REF!,MATCH(B4&"|R"&15,#REF!,0)),"") | B33: =IFERROR(INDEX(#REF!,MATCH(B4&"|R"&15,#REF!,0)),"") | C33: =IFERROR(INDEX(#REF!,MATCH(B4&"|R"&15,#REF!,0)),"") | D33: =IFERROR(INDEX(#REF!,MATCH(B4&"|R"&15,#REF!,0)),"") | E33: =IFERROR(INDEX(#REF!,MATCH(B4&"|R"&15,#REF!,0)),"") | F33: =IFERROR(INDEX(#REF!,MATCH(B4&"|R"&15,#REF!,0)),"")
A34: =IFERROR(INDEX(#REF!,MATCH(B4&"|R"&16,#REF!,0)),"") | B34: =IFERROR(INDEX(#REF!,MATCH(B4&"|R"&16,#REF!,0)),"") | C34: =IFERROR(INDEX(#REF!,MATCH(B4&"|R"&16,#REF!,0)),"") | D34: =IFERROR(INDEX(#REF!,MATCH(B4&"|R"&16,#REF!,0)),"") | E34: =IFERROR(INDEX(#REF!,MATCH(B4&"|R"&16,#REF!,0)),"") | F34: =IFERROR(INDEX(#REF!,MATCH(B4&"|R"&16,#REF!,0)),"")
A35: =IFERROR(INDEX(#REF!,MATCH(B4&"|R"&17,#REF!,0)),"") | B35: =IFERROR(INDEX(#REF!,MATCH(B4&"|R"&17,#REF!,0)),"") | C35: =IFERROR(INDEX(#REF!,MATCH(B4&"|R"&17,#REF!,0)),"") | D35: =IFERROR(INDEX(#REF!,MATCH(B4&"|R"&17,#REF!,0)),"") | E35: =IFERROR(INDEX(#REF!,MATCH(B4&"|R"&17,#REF!,0)),"") | F35: =IFERROR(INDEX(#REF!,MATCH(B4&"|R"&17,#REF!,0)),"")
A36: =IFERROR(INDEX(#REF!,MATCH(B4&"|R"&18,#REF!,0)),"") | B36: =IFERROR(INDEX(#REF!,MATCH(B4&"|R"&18,#REF!,0)),"") | C36: =IFERROR(INDEX(#REF!,MATCH(B4&"|R"&18,#REF!,0)),"") | D36: =IFERROR(INDEX(#REF!,MATCH(B4&"|R"&18,#REF!,0)),"") | E36: =IFERROR(INDEX(#REF!,MATCH(B4&"|R"&18,#REF!,0)),"") | F36: =IFERROR(INDEX(#REF!,MATCH(B4&"|R"&18,#REF!,0)),"")
A37: =IFERROR(INDEX(#REF!,MATCH(B4&"|R"&19,#REF!,0)),"") | B37: =IFERROR(INDEX(#REF!,MATCH(B4&"|R"&19,#REF!,0)),"") | C37: =IFERROR(INDEX(#REF!,MATCH(B4&"|R"&19,#REF!,0)),"") | D37: =IFERROR(INDEX(#REF!,MATCH(B4&"|R"&19,#REF!,0)),"") | E37: =IFERROR(INDEX(#REF!,MATCH(B4&"|R"&19,#REF!,0)),"") | F37: =IFERROR(INDEX(#REF!,MATCH(B4&"|R"&19,#REF!,0)),"")
A38: =IFERROR(INDEX(#REF!,MATCH(B4&"|R"&20,#REF!,0)),"") | B38: =IFERROR(INDEX(#REF!,MATCH(B4&"|R"&20,#REF!,0)),"") | C38: =IFERROR(INDEX(#REF!,MATCH(B4&"|R"&20,#REF!,0)),"") | D38: =IFERROR(INDEX(#REF!,MATCH(B4&"|R"&20,#REF!,0)),"") | E38: =IFERROR(INDEX(#REF!,MATCH(B4&"|R"&20,#REF!,0)),"") | F38: =IFERROR(INDEX(#REF!,MATCH(B4&"|R"&20,#REF!,0)),"")
A40: Les 20 premiers mouvements enregistres pour ce materiel (dans l'ordre de saisie) s'affichent ci-dessus. Au-dela de 20 mouvements, consultez directement la feuille Affectations filtree sur ce Code Materiel.

Sheet Alertes
A1: ALERTES STOCK - SITUATION AU 14/07/2026
A2: Photo des articles CRITIQUE / RUPTURE au moment de la generation du fichier. Pour une vue toujours a jour, utilisez le filtre automatique sur la colonne Statut de la feuille Stock_TempsReel.
A4: Code Article | B4: Designation | C4: Famille | D4: Stock Actuel | E4: Stock Min | F4: Statut
A5: FO-0002 | B5: Collier blanc petit | C5: FO | D5: 0 | E5: 5 | F5: RUPTURE
A6: FO-0003 | B6: Dispositif de suspension JHC10-15 | C6: FO | D6: 0 | E6: 5 | F6: RUPTURE
A7: FO-0004 | B7: Dispositif de suspension JHC15-20 | C7: FO | D7: 0 | E7: 5 | F7: RUPTURE
A8: FO-0006 | B8: Entraxe 5/33 | C8: FO | D8: 0 | E8: 5 | F8: RUPTURE
A9: FO-0007 | B9: Feuillard inox 20x0,7 (rl 50m) | C9: FO | D9: 1 | E9: 5 | F9: CRITIQUE
A10: FO-0008 | B10: End box 2 core | C10: FO | D10: 0 | E10: 5 | F10: RUPTURE
A11: FO-0010 | B11: Pince d'ancrage FO ADSS12 | C11: FO | D11: 0 | E11: 5 | F11: RUPTURE
A12: FO-0011 | B12: Pince d'ancrage FO ADSS6 | C12: FO | D12: 0 | E12: 5 | F12: RUPTURE
A13: FO-0012 | B13: Semelle à goupille | C13: FO | D13: 0 | E13: 5 | F13: RUPTURE
A14: FO-0013 | B14: Boulon M12*30 | C14: FO | D14: 0 | E14: 5 | F14: RUPTURE
A15: FO-0014 | B15: Traverse 5/14 11 trous | C15: FO | D15: 0 | E15: 5 | F15: RUPTURE
A16: FO-0015 | B16: Pigtail | C16: FO | D16: 4 | E16: 5 | F16: CRITIQUE
... A194: NEW-0010 | B194: Silicone | C194: BLR (a classer) | D194: 0 | E194: 5 | F194: RUPTURE

Sheet Alertes_Tracabilite
A1: ALERTES INTELLIGENTES - TRACABILITE DU MATERIEL
A3: Retours en retard | C3: Doublons de numero de serie | E3: Affectations doubles suspectes | G3: Garanties expirant sous 60 jours | I3: Materiels sans mouvement > 180 jours
A4: =COUNTIF(#REF!,"OUI") -> #REF! | C4: =SUMPRODUCT((COUNTIFS(#REF!,#REF!)>1)*(#REF!<>"")) -> #REF! | E4: =COUNTIF(#REF!,"OUI") -> #REF! | G4: =SUMPRODUCT((#REF!<>"")*(#REF!-TODAY()<=60)*(#REF!-TODAY()>=0)) -> #REF! | I4: =SUMPRODUCT((#REF!<>"")*(#REF!>180)) -> #REF!
A8: Pour visualiser directement les lignes concernees : filtrez la colonne 'Retard' (feuille Affectations) sur OUI, la colonne 'Anomalie Double Affectation' (feuille Affectations) sur OUI, ou triez la feuille Equipements par colonne 'Numero de serie' / 'Garantie jusqu au' / 'Jours Depuis Dernier Mouvement'. Les cellules concernees y sont deja mises en evidence par mise en forme conditionnelle.
A11: MATERIELS EN RETARD DE RETOUR
A12: N Mouvement | B12: Code Materiel | C12: Projet | D12: Employe Beneficiaire | E12: Date retour prevue | F12: Jours de retard
A13: =IFERROR(INDEX(#REF!,MATCH("RETARD|R"&1,#REF!,0)),"") | B13: =IFERROR(INDEX(#REF!,MATCH("RETARD|R"&1,#REF!,0)),"") | C13: =IFERROR(INDEX(#REF!,MATCH("RETARD|R"&1,#REF!,0)),"") | D13: =IFERROR(INDEX(#REF!,MATCH("RETARD|R"&1,#REF!,0)),"") | E13: =IFERROR(INDEX(#REF!,MATCH("RETARD|R"&1,#REF!,0)),"") | F13: =IF(E13<>"",TODAY()-E13,"")
A14: =IFERROR(INDEX(#REF!,MATCH("RETARD|R"&2,#REF!,0)),"") | B14: =IFERROR(INDEX(#REF!,MATCH("RETARD|R"&2,#REF!,0)),"") | C14: =IFERROR(INDEX(#REF!,MATCH("RETARD|R"&2,#REF!,0)),"") | D14: =IFERROR(INDEX(#REF!,MATCH("RETARD|R"&2,#REF!,0)),"") | E14: =IFERROR(INDEX(#REF!,MATCH("RETARD|R"&2,#REF!,0)),"") | F14: =IF(E14<>"",TODAY()-E14,"")
A15: =IFERROR(INDEX(#REF!,MATCH("RETARD|R"&3,#REF!,0)),"") | B15: =IFERROR(INDEX(#REF!,MATCH("RETARD|R"&3,#REF!,0)),"") | C15: =IFERROR(INDEX(#REF!,MATCH("RETARD|R"&3,#REF!,0)),"") | D15: =IFERROR(INDEX(#REF!,MATCH("RETARD|R"&3,#REF!,0)),"") | E15: =IFERROR(INDEX(#REF!,MATCH("RETARD|R"&3,#REF!,0)),"") | F15: =IF(E15<>"",TODAY()-E15,"")
A16: =IFERROR(INDEX(#REF!,MATCH("RETARD|R"&4,#REF!,0)),"") | B16: =IFERROR(INDEX(#REF!,MATCH("RETARD|R"&4,#REF!,0)),"") | C16: =IFERROR(INDEX(#REF!,MATCH("RETARD|R"&4,#REF!,0)),"") | D16: =IFERROR(INDEX(#REF!,MATCH("RETARD|R"&4,#REF!,0)),"") | E16: =IFERROR(INDEX(#REF!,MATCH("RETARD|R"&4,#REF!,0)),"") | F16: =IF(E16<>"",TODAY()-E16,"")
A17: =IFERROR(INDEX(#REF!,MATCH("RETARD|R"&5,#REF!,0)),"") | B17: =IFERROR(INDEX(#REF!,MATCH("RETARD|R"&5,#REF!,0)),"") | C17: =IFERROR(INDEX(#REF!,MATCH("RETARD|R"&5,#REF!,0)),"") | D17: =IFERROR(INDEX(#REF!,MATCH("RETARD|R"&5,#REF!,0)),"") | E17: =IFERROR(INDEX(#REF!,MATCH("RETARD|R"&5,#REF!,0)),"") | F17: =IF(E17<>"",TODAY()-E17,"")
A18: =IFERROR(INDEX(#REF!,MATCH("RETARD|R"&6,#REF!,0)),"") | B18: =IFERROR(INDEX(#REF!,MATCH("RETARD|R"&6,#REF!,0)),"") | C18: =IFERROR(INDEX(#REF!,MATCH("RETARD|R"&6,#REF!,0)),"") | D18: =IFERROR(INDEX(#REF!,MATCH("RETARD|R"&6,#REF!,0)),"") | E18: =IFERROR(INDEX(#REF!,MATCH("RETARD|R"&6,#REF!,0)),"") | F18: =IF(E18<>"",TODAY()-E18,"")
A19: =IFERROR(INDEX(#REF!,MATCH("RETARD|R"&7,#REF!,0)),"") | B19: =IFERROR(INDEX(#REF!,MATCH("RETARD|R"&7,#REF!,0)),"") | C19: =IFERROR(INDEX(#REF!,MATCH("RETARD|R"&7,#REF!,0)),"") | D19: =IFERROR(INDEX(#REF!,MATCH("RETARD|R"&7,#REF!,0)),"") | E19: =IFERROR(INDEX(#REF!,MATCH("RETARD|R"&7,#REF!,0)),"") | F19: =IF(E19<>"",TODAY()-E19,"")
